Workbook

Sheet Analysis
B1: NAV Build-up
C2: Year 1 | D2: Year 2 | E2: Year 3 | F2: Year 4 | G2: Year 5 | H2: Year 6 | I2: Year 7 | J2: Year 8 | K2: Year 9 | L2: Year 10 | M2: Year 11 | N2: Year 12 | O2: Year 13 | P2: Year 14 | Q2: Year 15
B3: Drawdown only | C3: ='Drawdown only'!D208 -> 0.61979885 | D3: ='Drawdown only'!E208 -> 1.9975294 | E3: ='Drawdown only'!F208 -> 4.2384224 | F3: ='Drawdown only'!G208 -> 7.1673385 | G3: ='Drawdown only'!H208 -> 10.451436 | H3: ='Drawdown only'!I208 -> 13.593923 | I3: ='Drawdown only'!J208 -> 16.455815 | J3: ='Drawdown only'!K208 -> 18.881824 | ... Q3: ='Drawdown only'!R208 -> 26.296312
B4: Evergreen only | C4: ='Evergreen only'!D208 -> 10.939 | D4: ='Evergreen only'!E208 -> 11.966172 | E4: ='Evergreen only'!F208 -> 13.089796 | F4: ='Evergreen only'!G208 -> 14.318927 | G4: ='Evergreen only'!H208 -> 15.663475 | H4: ='Evergreen only'!I208 -> 17.134275 | I4: ='Evergreen only'!J208 -> 18.743183 | J4: ='Evergreen only'!K208 -> 20.503168 | ... Q4: ='Evergreen only'!R208 -> 38.429465
B5: Drawdown with re-investment | C5: ='Drawdown+reinvestment'!D208 -> 10.600656 | D5: ='Drawdown+reinvestment'!E208 -> 11.132372 | E5: ='Drawdown+reinvestment'!F208 -> 11.668652 | F5: ='Drawdown+reinvestment'!G208 -> 12.356559 | G5: ='Drawdown+reinvestment'!H208 -> 13.4591 | H5: ='Drawdown+reinvestment'!I208 -> 14.787801 | I5: ='Drawdown+reinvestment'!J208 -> 16.636856 | J5: ='Drawdown+reinvestment'!K208 -> 18.924892 | ... Q5: ='Drawdown+reinvestment'!R208 -> 42.613909
B6: Drawdown and Evergreen | C6: ='Drawdown+Evergreen from start'!D208 -> 10.769828 | D6: ='Drawdown+Evergreen from start'!E208 -> 11.549272 | E6: ='Drawdown+Evergreen from start'!F208 -> 12.379224 | F6: ='Drawdown+Evergreen from start'!G208 -> 13.337743 | G6: ='Drawdown+Evergreen from start'!H208 -> 14.561287 | H6: ='Drawdown+Evergreen from start'!I208 -> 15.961038 | I6: ='Drawdown+Evergreen from start'!J208 -> 17.69002 | J6: ='Drawdown+Evergreen from start'!K208 -> 19.71403 | ... Q6: ='Drawdown+Evergreen from start'!R208 -> 40.521687

Sheet Drawdown only
A1: After-tax annualized investment return: | B1: 0.064
A3: Year | B3: Current Market Value | C3: New Money Ins/Outs | D3: Total Assets | E3: PE Target (%) | F3: PE Target ($) | H3: Compounding Open-ended PE Commitments | I3: Compounding Rate | K3: Yielding Open-ended PE Commitments | L3: Yield Rate | N3: New Drawdown Target Portfolio | O3: **Make sure this sums to 100%
A4: 2025 | B4: 10000000 | C4: 0 | D4: =SUM(B4:C4) -> 10000000 | E4: 1 | F4: =D4*E4 -> 10000000 | H4: 0 | I4: 0.09 | K4: 0 | L4: 0.06 | N4: Buyout | O4: 1
A5: =A4+1 -> 2026 | D5: =(D4*(1+$B$1))+C5 -> 10640000 | E5: =E4 -> 1 | F5: =D5*E5 -> 10640000 | H5: 0 | K5: 0 | N5: Growth Equity | O5: 0
A6: =A5+1 -> 2027 | D6: =(D5*(1+$B$1))+C6 -> 11320960 | E6: =E5 -> 1 | F6: =D6*E6 -> 11320960 | H6: 0 | K6: 0 | N6: Venture Capital | O6: 0
A7: =A6+1 -> 2028 | D7: =(D6*(1+$B$1))+C7 -> 12045501 | E7: =E6 -> 1 | F7: =D7*E7 -> 12045501 | H7: 0 | K7: 0 | N7: Fund of Funds | O7: 0
A8: =A7+1 -> 2029 | D8: =(D7*(1+$B$1))+C8 -> 12816414 | E8: =E7 -> 1 | F8: =D8*E8 -> 12816414 | H8: 0 | K8: 0 | N8: Secondary Funds | O8: 0
A9: =A8+1 -> 2030 | D9: =(D8*(1+$B$1))+C9 -> 13636664 | E9: =E8 -> 1 | F9: =D9*E9 -> 13636664 | H9: 0 | K9: 0 | N9: Private Credit | O9: 0
A10: =A9+1 -> 2031 | D10: =(D9*(1+$B$1))+C10 -> 14509410 | E10: =E9 -> 1 | F10: =D10*E10 -> 14509410 | H10: 0 | K10: 0 | N10: Real Estate | O10: 0
A11: =A10+1 -> 2032 | D11: =(D10*(1+$B$1))+C11 -> 15438013 | E11: =E10 -> 1 | F11: =D11*E11 -> 15438013 | H11: 0 | K11: 0
A12: =A11+1 -> 2033 | D12: =(D11*(1+$B$1))+C12 -> 16426046 | E12: =E11 -> 1 | F12: =D12*E12 -> 16426046 | H12: 0 | K12: 0 | N12: Total | O12: =SUM(O4:O10) -> 1
A13: =A12+1 -> 2034 | D13: =(D12*(1+$B$1))+C13 -> 17477313 | E13: =E12 -> 1 | F13: =D13*E13 -> 17477313 | H13: 0 | K13: 0
A14: =A13+1 -> 2035 | D14: =(D13*(1+$B$1))+C14 -> 18595861 | E14: =E13 -> 1 | F14: =D14*E14 -> 18595861 | H14: 0 | K14: 0
A15: =A14+1 -> 2036 | D15: =(D14*(1+$B$1))+C15 -> 19785996 | E15: =E14 -> 1 | F15: =D15*E15 -> 19785996 | H15: 0 | K15: 0
A16: =A15+1 -> 2037 | D16: =(D15*(1+$B$1))+C16 -> 21052299 | E16: =E15 -> 1 | F16: =D16*E16 -> 21052299 | H16: 0 | K16: 0
A17: =A16+1 -> 2038 | D17: =(D16*(1+$B$1))+C17 -> 22399646 | E17: =E16 -> 1 | F17: =D17*E17 -> 22399646 | H17: 0 | K17: 0
A18: =A17+1 -> 2039 | D18: =(D17*(1+$B$1))+C18 -> 23833224 | E18: =E17 -> 1 | F18: =D18*E18 -> 23833224 | H18: 0 | K18: 0
A27: EXISTING PORTFOLIO | B27: TO FILL IN WITH CONNECT OUTPUT | D27: Net Asset Value
A28: New Commitments | B28: Commitment | C28: % of Total Portfolio Value | D28: 2025 | E28: =D28+1 -> 2026 | F28: =E28+1 -> 2027 | G28: =F28+1 -> 2028 | H28: =G28+1 -> 2029 | I28: =H28+1 -> 2030 | J28: =I28+1 -> 2031 | K28: =J28+1 -> 2032 | L28: =K28+1 -> 2033 | ... R28: =Q28+1 -> 2039
B30: 0 | D30: 0 | E30: 0 | F30: 0 | G30: 0 | H30: 0 | I30: 0 | J30: 0 | K30: 0 | L30: 0 | M30: 0 | N30: 0 | O30: 0 | P30: 0 | Q30: 0 | R30: 0
D33: Annual Capital Called
A34: New Commitments | B34: Commitment | D34: =D$100 -> 2025 | E34: =E$100 -> 2026 | F34: =F$100 -> 2027 | G34: =G$100 -> 2028 | H34: =H$100 -> 2029 | I34: =I$100 -> 2030 | J34: =J$100 -> 2031 | K34: =K$100 -> 2032 | ... R34: =R$100 -> 2039
B36: 0 | D36: 0 | E36: 0 | F36: 0 | G36: 0 | H36: 0 | I36: 0 | J36: 0 | K36: 0 | L36: 0 | M36: 0 | N36: 0 | O36: 0 | P36: 0 | Q36: 0 | R36: 0
D38: Annual Distributions
A39: New Commitments | B39: Commitment | D39: =D$100 -> 2025 | E39: =E$100 -> 2026 | F39: =F$100 -> 2027 | G39: =G$100 -> 2028 | H39: =H$100 -> 2029 | I39: =I$100 -> 2030 | J39: =J$100 -> 2031 | K39: =K$100 -> 2032 | ... R39: =R$100 -> 2039
B41: 0 | D41: 0 | E41: 0 | F41: 0 | G41: 0 | H41: 0 | I41: 0 | J41: 0 | K41: 0 | L41: 0 | M41: 0 | N41: 0 | O41: 0 | P41: 0 | Q41: 0 | R41: 0
D43: Net Cash Flow
A44: New Commitments | B44: Commitment | D44: =D$100 -> 2025 | E44: =E$100 -> 2026 | F44: =F$100 -> 2027 | G44: =G$100 -> 2028 | H44: =H$100 -> 2029 | I44: =I$100 -> 2030 | J44: =J$100 -> 2031 | K44: =K$100 -> 2032 | ... R44: =R$100 -> 2039
B46: 0 | D46: =D36+D41 -> 0 | E46: =E36+E41 -> 0 | F46: =F36+F41 -> 0 | G46: =G36+G41 -> 0 | H46: =H36+H41 -> 0 | I46: =I36+I41 -> 0 | J46: =J36+J41 -> 0 | K46: =K36+K41 -> 0 | ... R46: =R36+R41 -> 0
A49: Net Cash Flow Cumulative | D49: =D46 -> 0 | E49: =D49+E46 -> 0 | F49: =E49+F46 -> 0 | G49: =F49+G46 -> 0 | H49: =G49+H46 -> 0 | I49: =H49+I46 -> 0 | J49: =I49+J46 -> 0 | K49: =J49+K46 -> 0 | L49: =K49+L46 -> 0 | ... R49: =Q49+R46 -> 0
A51: Cash invested | D51: Net Asset Value
A52: New Commitments | B52: Commitment | C52: % of Total Portfolio Value | D52: 2025 | E52: =D52+1 -> 2026 | F52: =E52+1 -> 2027 | G52: =F52+1 -> 2028 | H52: =G52+1 -> 2029 | I52: =H52+1 -> 2030 | J52: =I52+1 -> 2031 | K52: =J52+1 -> 2032 | L52: =K52+1 -> 2033 | ... R52: =Q52+1 -> 2039
B54: =SUM(K4:K18) -> 0 | C54: =B4 -> 10000000 | D54: =$K4 -> 0 | E54: =K4+K5 -> 0 | F54: =K4+K6+K5 -> 0 | G54: =K4+K5+K6+K7 -> 0 | H54: =K4+K5+K6+K7+K8 -> 0 | I54: =K4+K5+K6+K7+K8+K9 -> 0 | J54: =K4+K5+K6+K7+K8+K9+K10 -> 0 | K54: =K4+K5+K6+K7+K8+K9+K10+K11 -> 0 | L54: =K4+K5+K6+K7+K8+K9+K10+K11+K12 -> 0 | M54: =K4+K5+K6+K7+K8+K9+K10+K11+K12+K13 -> 0 | N54: =K4+K5+K6+K7+K8+K9+K10+K11+K12+K13+K14 -> 0 | O54: =K4+K5+K6+K7+K8+K9+K10+K11+K12+K13+K14+K15 -> 0 | P54: =K4+K5+K6+K7+K8+K9+K10+K11+K12+K13+K14+K15+K16 -> 0 | Q54: =K4+K5+K6+K7+K8+K9+K10+K11+K12+K13+K14+K15+K16+K17 -> 0 | R54: =K4+K5+K6+K7+K8+K9+K10+K11+K12+K13+K14+K15+K16+K17+K18 -> 0
D57: Annual Capital Called
A58: New Commitments | B58: Commitment | D58: =D$100 -> 2025 | E58: =E$100 -> 2026 | F58: =F$100 -> 2027 | G58: =G$100 -> 2028 | H58: =H$100 -> 2029 | I58: =I$100 -> 2030 | J58: =J$100 -> 2031 | K58: =K$100 -> 2032 | ... R58: =R$100 -> 2039
B60: =SUM(K4:K18) -> 0 | D60: =-K4 -> 0 | E60: =-$K5 -> 0 | F60: =-$K6 -> 0 | G60: =-$K7 -> 0 | H60: =-$K8 -> 0 | I60: =-$K9 -> 0 | J60: =-$K10 -> 0 | K60: =-$K11 -> 0 | L60: =-$K12 -> 0 | M60: =-$K13 -> 0 | N60: =-$K14 -> 0 | O60: =-$K15 -> 0 | P60: =-$K16 -> 0 | Q60: =-$K17 -> 0 | R60: =-$K18 -> 0
D62: Annual Distributions
A63: New Commitments | B63: Commitment | D63: =D$100 -> 2025 | E63: =E$100 -> 2026 | F63: =F$100 -> 2027 | G63: =G$100 -> 2028 | H63: =H$100 -> 2029 | I63: =I$100 -> 2030 | J63: =J$100 -> 2031 | K63: =K$100 -> 2032 | ... R63: =R$100 -> 2039
B65: =SUM(K4:K18) -> 0 | D65: =K4*$L$4 -> 0 | E65: =SUM($K4:$K5)*$L$4 -> 0 | F65: =SUM($K4:$K6)*$L$4 -> 0 | G65: =SUM($K4:$K7)*$L$4 -> 0 | H65: =SUM($K4:$K8)*$L$4 -> 0 | I65: =SUM($K4:$K9)*$L$4 -> 0 | J65: =SUM($K4:$K10)*$L$4 -> 0 | K65: =SUM($K4:$K11)*$L$4 -> 0 | L65: =SUM($K4:$K12)*$L$4 -> 0 | M65: =SUM($K4:$K13)*$L$4 -> 0 | N65: =SUM($K4:$K14)*$L$4 -> 0 | O65: =SUM($K4:$K15)*$L$4 -> 0 | P65: =SUM($K4:$K16)*$L$4 -> 0 | Q65: =SUM($K4:$K17)*$L$4 -> 0 | R65: =SUM($K4:$K18)*$L$4 -> 0
D67: Net Cash Flow
...

Sheet Evergreen only
A1: After-tax annualized investment return: | B1: 0.064
A3: Year | B3: Current Market Value | C3: New Money Ins/Outs | D3: Total Assets | E3: PE Target (%) | F3: PE Target ($) | H3: Compounding Open-ended PE Commitments | I3: Compounding Rate | K3: Yielding Open-ended PE Commitments | L3: Yield Rate | N3: New Drawdown Target Portfolio | O3: **Make sure this sums to 100%
A4: 2025 | B4: 10000000 | C4: 0 | D4: =SUM(B4:C4) -> 10000000 | E4: 1 | F4: =D4*E4 -> 10000000 | H4: 10000000 | I4: =LTCMAs!K11 -> 0.0939 | K4: 0 | L4: 0.06 | N4: Buyout | O4: 1
A5: =A4+1 -> 2026 | D5: =(D4*(1+$B$1))+C5 -> 10640000 | E5: =E4 -> 1 | F5: =D5*E5 -> 10640000 | H5: 0 | K5: 0 | N5: Growth Equity | O5: 0
A6: =A5+1 -> 2027 | D6: =(D5*(1+$B$1))+C6 -> 11320960 | E6: =E5 -> 1 | F6: =D6*E6 -> 11320960 | H6: 0 | K6: 0 | N6: Venture Capital | O6: 0
A7: =A6+1 -> 2028 | D7: =(D6*(1+$B$1))+C7 -> 12045501 | E7: =E6 -> 1 | F7: =D7*E7 -> 12045501 | H7: 0 | K7: 0 | N7: Fund of Funds | O7: 0
A8: =A7+1 -> 2029 | D8: =(D7*(1+$B$1))+C8 -> 12816414 | E8: =E7 -> 1 | F8: =D8*E8 -> 12816414 | H8: 0 | K8: 0 | N8: Secondary Funds | O8: 0
A9: =A8+1 -> 2030 | D9: =(D8*(1+$B$1))+C9 -> 13636664 | E9: =E8 -> 1 | F9: =D9*E9 -> 13636664 | H9: 0 | K9: 0 | N9: Private Credit | O9: 0
A10: =A9+1 -> 2031 | D10: =(D9*(1+$B$1))+C10 -> 14509410 | E10: =E9 -> 1 | F10: =D10*E10 -> 14509410 | H10: 0 | K10: 0 | N10: Real Estate | O10: 0
A11: =A10+1 -> 2032 | D11: =(D10*(1+$B$1))+C11 -> 15438013 | E11: =E10 -> 1 | F11: =D11*E11 -> 15438013 | H11: 0 | K11: 0
A12: =A11+1 -> 2033 | D12: =(D11*(1+$B$1))+C12 -> 16426046 | E12: =E11 -> 1 | F12: =D12*E12 -> 16426046 | H12: 0 | K12: 0 | N12: Total | O12: =SUM(O4:O10) -> 1
A13: =A12+1 -> 2034 | D13: =(D12*(1+$B$1))+C13 -> 17477313 | E13: =E12 -> 1 | F13: =D13*E13 -> 17477313 | H13: 0 | K13: 0
A14: =A13+1 -> 2035 | D14: =(D13*(1+$B$1))+C14 -> 18595861 | E14: =E13 -> 1 | F14: =D14*E14 -> 18595861 | H14: 0 | K14: 0
A15: =A14+1 -> 2036 | D15: =(D14*(1+$B$1))+C15 -> 19785996 | E15: =E14 -> 1 | F15: =D15*E15 -> 19785996 | H15: 0 | K15: 0
A16: =A15+1 -> 2037 | D16: =(D15*(1+$B$1))+C16 -> 21052299 | E16: =E15 -> 1 | F16: =D16*E16 -> 21052299 | H16: 0 | K16: 0
A17: =A16+1 -> 2038 | D17: =(D16*(1+$B$1))+C17 -> 22399646 | E17: =E16 -> 1 | F17: =D17*E17 -> 22399646 | H17: 0 | K17: 0
A18: =A17+1 -> 2039 | D18: =(D17*(1+$B$1))+C18 -> 23833224 | E18: =E17 -> 1 | F18: =D18*E18 -> 23833224 | H18: 0 | K18: 0
A27: EXISTING PORTFOLIO | B27: TO FILL IN WITH CONNECT OUTPUT | D27: Net Asset Value
A28: New Commitments | B28: Commitment | C28: % of Total Portfolio Value | D28: 2025 | E28: =D28+1 -> 2026 | F28: =E28+1 -> 2027 | G28: =F28+1 -> 2028 | H28: =G28+1 -> 2029 | I28: =H28+1 -> 2030 | J28: =I28+1 -> 2031 | K28: =J28+1 -> 2032 | L28: =K28+1 -> 2033 | ... R28: =Q28+1 -> 2039
B30: 0 | D30: 0 | E30: 0 | F30: 0 | G30: 0 | H30: 0 | I30: 0 | J30: 0 | K30: 0 | L30: 0 | M30: 0 | N30: 0 | O30: 0 | P30: 0 | Q30: 0 | R30: 0
D33: Annual Capital Called
A34: New Commitments | B34: Commitment | D34: =D$100 -> 2025 | E34: =E$100 -> 2026 | F34: =F$100 -> 2027 | G34: =G$100 -> 2028 | H34: =H$100 -> 2029 | I34: =I$100 -> 2030 | J34: =J$100 -> 2031 | K34: =K$100 -> 2032 | ... R34: =R$100 -> 2039
B36: 0 | D36: 0 | E36: 0 | F36: 0 | G36: 0 | H36: 0 | I36: 0 | J36: 0 | K36: 0 | L36: 0 | M36: 0 | N36: 0 | O36: 0 | P36: 0 | Q36: 0 | R36: 0
D38: Annual Distributions
A39: New Commitments | B39: Commitment | D39: =D$100 -> 2025 | E39: =E$100 -> 2026 | F39: =F$100 -> 2027 | G39: =G$100 -> 2028 | H39: =H$100 -> 2029 | I39: =I$100 -> 2030 | J39: =J$100 -> 2031 | K39: =K$100 -> 2032 | ... R39: =R$100 -> 2039
B41: 0 | D41: 0 | E41: 0 | F41: 0 | G41: 0 | H41: 0 | I41: 0 | J41: 0 | K41: 0 | L41: 0 | M41: 0 | N41: 0 | O41: 0 | P41: 0 | Q41: 0 | R41: 0
D43: Net Cash Flow
A44: New Commitments | B44: Commitment | D44: =D$100 -> 2025 | E44: =E$100 -> 2026 | F44: =F$100 -> 2027 | G44: =G$100 -> 2028 | H44: =H$100 -> 2029 | I44: =I$100 -> 2030 | J44: =J$100 -> 2031 | K44: =K$100 -> 2032 | ... R44: =R$100 -> 2039
B46: 0 | D46: =D36+D41 -> 0 | E46: =E36+E41 -> 0 | F46: =F36+F41 -> 0 | G46: =G36+G41 -> 0 | H46: =H36+H41 -> 0 | I46: =I36+I41 -> 0 | J46: =J36+J41 -> 0 | K46: =K36+K41 -> 0 | ... R46: =R36+R41 -> 0
A49: Net Cash Flow Cumulative | D49: =D46 -> 0 | E49: =D49+E46 -> 0 | F49: =E49+F46 -> 0 | G49: =F49+G46 -> 0 | H49: =G49+H46 -> 0 | I49: =H49+I46 -> 0 | J49: =I49+J46 -> 0 | K49: =J49+K46 -> 0 | L49: =K49+L46 -> 0 | ... R49: =Q49+R46 -> 0
A51: NEW YIELDING OPEN-ENDED PORTFOLIO | D51: Net Asset Value
A52: New Commitments | B52: Commitment | C52: % of Total Portfolio Value | D52: 2025 | E52: =D52+1 -> 2026 | F52: =E52+1 -> 2027 | G52: =F52+1 -> 2028 | H52: =G52+1 -> 2029 | I52: =H52+1 -> 2030 | J52: =I52+1 -> 2031 | K52: =J52+1 -> 2032 | L52: =K52+1 -> 2033 | ... R52: =Q52+1 -> 2039
B54: =SUM(K4:K18) -> 0 | D54: =$K4 -> 0 | E54: =K4+K5 -> 0 | F54: =K4+K6+K5 -> 0 | G54: =K4+K5+K6+K7 -> 0 | H54: =K4+K5+K6+K7+K8 -> 0 | I54: =K4+K5+K6+K7+K8+K9 -> 0 | J54: =K4+K5+K6+K7+K8+K9+K10 -> 0 | K54: =K4+K5+K6+K7+K8+K9+K10+K11 -> 0 | L54: =K4+K5+K6+K7+K8+K9+K10+K11+K12 -> 0 | M54: =K4+K5+K6+K7+K8+K9+K10+K11+K12+K13 -> 0 | N54: =K4+K5+K6+K7+K8+K9+K10+K11+K12+K13+K14 -> 0 | O54: =K4+K5+K6+K7+K8+K9+K10+K11+K12+K13+K14+K15 -> 0 | P54: =K4+K5+K6+K7+K8+K9+K10+K11+K12+K13+K14+K15+K16 -> 0 | Q54: =K4+K5+K6+K7+K8+K9+K10+K11+K12+K13+K14+K15+K16+K17 -> 0 | R54: =K4+K5+K6+K7+K8+K9+K10+K11+K12+K13+K14+K15+K16+K17+K18 -> 0
D57: Annual Capital Called
A58: New Commitments | B58: Commitment | D58: =D$100 -> 2025 | E58: =E$100 -> 2026 | F58: =F$100 -> 2027 | G58: =G$100 -> 2028 | H58: =H$100 -> 2029 | I58: =I$100 -> 2030 | J58: =J$100 -> 2031 | K58: =K$100 -> 2032 | ... R58: =R$100 -> 2039
B60: =SUM(K4:K18) -> 0 | D60: =-K4 -> 0 | E60: =-$K5 -> 0 | F60: =-$K6 -> 0 | G60: =-$K7 -> 0 | H60: =-$K8 -> 0 | I60: =-$K9 -> 0 | J60: =-$K10 -> 0 | K60: =-$K11 -> 0 | L60: =-$K12 -> 0 | M60: =-$K13 -> 0 | N60: =-$K14 -> 0 | O60: =-$K15 -> 0 | P60: =-$K16 -> 0 | Q60: =-$K17 -> 0 | R60: =-$K18 -> 0
D62: Annual Distributions
A63: New Commitments | B63: Commitment | D63: =D$100 -> 2025 | E63: =E$100 -> 2026 | F63: =F$100 -> 2027 | G63: =G$100 -> 2028 | H63: =H$100 -> 2029 | I63: =I$100 -> 2030 | J63: =J$100 -> 2031 | K63: =K$100 -> 2032 | ... R63: =R$100 -> 2039
B65: =SUM(K4:K18) -> 0 | D65: =K4*$L$4 -> 0 | E65: =SUM($K4:$K5)*$L$4 -> 0 | F65: =SUM($K4:$K6)*$L$4 -> 0 | G65: =SUM($K4:$K7)*$L$4 -> 0 | H65: =SUM($K4:$K8)*$L$4 -> 0 | I65: =SUM($K4:$K9)*$L$4 -> 0 | J65: =SUM($K4:$K10)*$L$4 -> 0 | K65: =SUM($K4:$K11)*$L$4 -> 0 | L65: =SUM($K4:$K12)*$L$4 -> 0 | M65: =SUM($K4:$K13)*$L$4 -> 0 | N65: =SUM($K4:$K14)*$L$4 -> 0 | O65: =SUM($K4:$K15)*$L$4 -> 0 | P65: =SUM($K4:$K16)*$L$4 -> 0 | Q65: =SUM($K4:$K17)*$L$4 -> 0 | R65: =SUM($K4:$K18)*$L$4 -> 0
D67: Net Cash Flow
...

Sheet Drawdown+reinvestment
A1: After-tax annualized investment return: | B1: 0.061
A3: Year | B3: Current Market Value | C3: New Money Ins/Outs | D3: Total Assets | E3: PE Target (%) | F3: PE Target ($) | H3: Compounding Open-ended PE Commitments | I3: Compounding Rate | K3: Yielding Open-ended PE Commitments | L3: Yield Rate | N3: New Drawdown Target Portfolio | O3: **Make sure this sums to 100%
A4: 2024 | B4: 10000000 | C4: 0 | D4: =SUM(B4:C4) -> 10000000 | E4: 1 | F4: =D4*E4 -> 10000000 | H4: 0 | I4: 0.1 | K4: 0 | L4: 0.061 | N4: Buyout | O4: 1
A5: =A4+1 -> 2025 | D5: =(D4*(1+$B$1))+C5 -> 10610000 | E5: =E4 -> 1 | F5: =D5*E5 -> 10610000 | H5: 0 | K5: 0 | N5: Growth Equity | O5: 0
A6: =A5+1 -> 2026 | D6: =(D5*(1+$B$1))+C6 -> 11257210 | E6: =E5 -> 1 | F6: =D6*E6 -> 11257210 | H6: 0 | K6: 0 | N6: Venture Capital | O6: 0
A7: =A6+1 -> 2027 | D7: =(D6*(1+$B$1))+C7 -> 11943900 | E7: =E6 -> 1 | F7: =D7*E7 -> 11943900 | H7: 0 | K7: 0 | N7: Fund of Funds | O7: 0
A8: =A7+1 -> 2028 | D8: =(D7*(1+$B$1))+C8 -> 12672478 | E8: =E7 -> 1 | F8: =D8*E8 -> 12672478 | H8: 0 | K8: 0 | N8: Secondary Funds | O8: 0
A9: =A8+1 -> 2029 | D9: =(D8*(1+$B$1))+C9 -> 13445499 | E9: =E8 -> 1 | F9: =D9*E9 -> 13445499 | H9: 0 | K9: 0 | N9: Private Credit | O9: 0
A10: =A9+1 -> 2030 | D10: =(D9*(1+$B$1))+C10 -> 14265674 | E10: =E9 -> 1 | F10: =D10*E10 -> 14265674 | H10: 0 | K10: 0 | N10: Real Estate | O10: 0
A11: =A10+1 -> 2031 | D11: =(D10*(1+$B$1))+C11 -> 15135880 | E11: =E10 -> 1 | F11: =D11*E11 -> 15135880 | H11: 0 | K11: 0
A12: =A11+1 -> 2032 | D12: =(D11*(1+$B$1))+C12 -> 16059169 | E12: =E11 -> 1 | F12: =D12*E12 -> 16059169 | H12: 0 | K12: 0 | N12: Total | O12: =SUM(O4:O10) -> 1
A13: =A12+1 -> 2033 | D13: =(D12*(1+$B$1))+C13 -> 17038778 | E13: =E12 -> 1 | F13: =D13*E13 -> 17038778 | H13: 0 | K13: 0
A14: =A13+1 -> 2034 | D14: =(D13*(1+$B$1))+C14 -> 18078144 | E14: =E13 -> 1 | F14: =D14*E14 -> 18078144 | H14: 0 | K14: 0
A15: =A14+1 -> 2035 | D15: =(D14*(1+$B$1))+C15 -> 19180911 | E15: =E14 -> 1 | F15: =D15*E15 -> 19180911 | H15: 0 | K15: 0
A16: =A15+1 -> 2036 | D16: =(D15*(1+$B$1))+C16 -> 20350946 | E16: =E15 -> 1 | F16: =D16*E16 -> 20350946 | H16: 0 | K16: 0
A17: =A16+1 -> 2037 | D17: =(D16*(1+$B$1))+C17 -> 21592354 | E17: =E16 -> 1 | F17: =D17*E17 -> 21592354 | H17: 0 | K17: 0
A18: =A17+1 -> 2038 | D18: =(D17*(1+$B$1))+C18 -> 22909488 | E18: =E17 -> 1 | F18: =D18*E18 -> 22909488 | H18: 0 | K18: 0
A27: EXISTING PORTFOLIO | B27: TO FILL IN WITH CONNECT OUTPUT | D27: Net Asset Value
A28: New Commitments | B28: Commitment | C28: % of Total Portfolio Value | D28: 2025 | E28: =D28+1 -> 2026 | F28: =E28+1 -> 2027 | G28: =F28+1 -> 2028 | H28: =G28+1 -> 2029 | I28: =H28+1 -> 2030 | J28: =I28+1 -> 2031 | K28: =J28+1 -> 2032 | L28: =K28+1 -> 2033 | ... R28: =Q28+1 -> 2039
B30: 0 | D30: 0 | E30: 0 | F30: 0 | G30: 0 | H30: 0 | I30: 0 | J30: 0 | K30: 0 | L30: 0 | M30: 0 | N30: 0 | O30: 0 | P30: 0 | Q30: 0 | R30: 0
D33: Annual Capital Called
A34: New Commitments | B34: Commitment | D34: =D$100 -> 2025 | E34: =E$100 -> 2026 | F34: =F$100 -> 2027 | G34: =G$100 -> 2028 | H34: =H$100 -> 2029 | I34: =I$100 -> 2030 | J34: =J$100 -> 2031 | K34: =K$100 -> 2032 | ... R34: =R$100 -> 2039
B36: 0 | D36: 0 | E36: 0 | F36: 0 | G36: 0 | H36: 0 | I36: 0 | J36: 0 | K36: 0 | L36: 0 | M36: 0 | N36: 0 | O36: 0 | P36: 0 | Q36: 0 | R36: 0
D38: Annual Distributions
A39: New Commitments | B39: Commitment | D39: =D$100 -> 2025 | E39: =E$100 -> 2026 | F39: =F$100 -> 2027 | G39: =G$100 -> 2028 | H39: =H$100 -> 2029 | I39: =I$100 -> 2030 | J39: =J$100 -> 2031 | K39: =K$100 -> 2032 | ... R39: =R$100 -> 2039
B41: 0 | D41: 0 | E41: 0 | F41: 0 | G41: 0 | H41: 0 | I41: 0 | J41: 0 | K41: 0 | L41: 0 | M41: 0 | N41: 0 | O41: 0 | P41: 0 | Q41: 0 | R41: 0
D43: Net Cash Flow
A44: New Commitments | B44: Commitment | D44: =D$100 -> 2025 | E44: =E$100 -> 2026 | F44: =F$100 -> 2027 | G44: =G$100 -> 2028 | H44: =H$100 -> 2029 | I44: =I$100 -> 2030 | J44: =J$100 -> 2031 | K44: =K$100 -> 2032 | ... R44: =R$100 -> 2039
B46: 0 | D46: =D36+D41 -> 0 | E46: =E36+E41 -> 0 | F46: =F36+F41 -> 0 | G46: =G36+G41 -> 0 | H46: =H36+H41 -> 0 | I46: =I36+I41 -> 0 | J46: =J36+J41 -> 0 | K46: =K36+K41 -> 0 | ... R46: =R36+R41 -> 0
A49: Net Cash Flow Cumulative | D49: =D46 -> 0 | E49: =D49+E46 -> 0 | F49: =E49+F46 -> 0 | G49: =F49+G46 -> 0 | H49: =G49+H46 -> 0 | I49: =H49+I46 -> 0 | J49: =I49+J46 -> 0 | K49: =J49+K46 -> 0 | L49: =K49+L46 -> 0 | ... R49: =Q49+R46 -> 0
A51: Cash invested | D51: Net Asset Value
A52: New Commitments | B52: Commitment | C52: % of Total Portfolio Value | D52: 2025 | E52: =D52+1 -> 2026 | F52: =E52+1 -> 2027 | G52: =F52+1 -> 2028 | H52: =G52+1 -> 2029 | I52: =H52+1 -> 2030 | J52: =I52+1 -> 2031 | K52: =J52+1 -> 2032 | L52: =K52+1 -> 2033 | ... R52: =Q52+1 -> 2039
B54: =SUM(K4:K18) -> 0 | C54: =B4 -> 10000000 | D54: =(C54+D146+D170)*(1+LTCMAs!$K$10) -> 9980857.2 | E54: =(D54+E146+E170)*(1+LTCMAs!$K$10) -> 9134842.1 | F54: =(E54+F146+F170)*(1+LTCMAs!$K$10) -> 7430230 | G54: =(F54+G146+G170)*(1+LTCMAs!$K$10) -> 5189220.4 | H54: =(G54+H146+H170)*(1+LTCMAs!$K$10) -> 3007663.6 | I54: =(H54+I146+I170)*(1+LTCMAs!$K$10) -> 1193878.3 | J54: =(I54+J146+J170)*(1+LTCMAs!$K$10) -> 181040.82 | K54: =(J54+K146+K170)*(1+LTCMAs!$K$10) -> 43067.34 | ... R54: =(Q54+R146+R170)*(1+LTCMAs!$K$10) -> 16317597
D57: Annual Capital Called
A58: New Commitments | B58: Commitment | D58: =D$100 -> 2025 | E58: =E$100 -> 2026 | F58: =F$100 -> 2027 | G58: =G$100 -> 2028 | H58: =H$100 -> 2029 | I58: =I$100 -> 2030 | J58: =J$100 -> 2031 | K58: =K$100 -> 2032 | ... R58: =R$100 -> 2039
B60: =SUM(K4:K18) -> 0 | D60: =-K4 -> 0 | E60: =-$K5 -> 0 | F60: =-$K6 -> 0 | G60: =-$K7 -> 0 | H60: =-$K8 -> 0 | I60: =-$K9 -> 0 | J60: =-$K10 -> 0 | K60: =-$K11 -> 0 | L60: =-$K12 -> 0 | M60: =-$K13 -> 0 | N60: =-$K14 -> 0 | O60: =-$K15 -> 0 | P60: =-$K16 -> 0 | Q60: =-$K17 -> 0 | R60: =-$K18 -> 0
D62: Annual Distributions
A63: New Commitments | B63: Commitment | D63: =D$100 -> 2025 | E63: =E$100 -> 2026 | F63: =F$100 -> 2027 | G63: =G$100 -> 2028 | H63: =H$100 -> 2029 | I63: =I$100 -> 2030 | J63: =J$100 -> 2031 | K63: =K$100 -> 2032 | ... R63: =R$100 -> 2039
B65: =SUM(K4:K18) -> 0 | D65: =K4*$L$4 -> 0 | E65: =SUM($K4:$K5)*$L$4 -> 0 | F65: =SUM($K4:$K6)*$L$4 -> 0 | G65: =SUM($K4:$K7)*$L$4 -> 0 | H65: =SUM($K4:$K8)*$L$4 -> 0 | I65: =SUM($K4:$K9)*$L$4 -> 0 | J65: =SUM($K4:$K10)*$L$4 -> 0 | K65: =SUM($K4:$K11)*$L$4 -> 0 | L65: =SUM($K4:$K12)*$L$4 -> 0 | M65: =SUM($K4:$K13)*$L$4 -> 0 | N65: =SUM($K4:$K14)*$L$4 -> 0 | O65: =SUM($K4:$K15)*$L$4 -> 0 | P65: =SUM($K4:$K16)*$L$4 -> 0 | Q65: =SUM($K4:$K17)*$L$4 -> 0 | R65: =SUM($K4:$K18)*$L$4 -> 0
D67: Net Cash Flow
...

Sheet Drawdown+Evergreen from start
A1: After-tax annualized investment return: | B1: 0.061
A3: Year | B3: Current Market Value | C3: New Money Ins/Outs | D3: Total Assets | E3: PE Target (%) | F3: PE Target ($) | H3: Compounding Open-ended PE Commitments | I3: Compounding Rate | K3: Yielding Open-ended PE Commitments | L3: Yield Rate | N3: New Drawdown Target Portfolio | O3: **Make sure this sums to 100%
A4: 2025 | B4: 10000000 | C4: 0 | D4: =SUM(B4:C4) -> 10000000 | E4: 1 | F4: =D4*E4 -> 10000000 | H4: 5000000 | I4: =LTCMAs!K11 -> 0.0939 | K4: 0 | L4: 0.06 | N4: Buyout | O4: 1
A5: =A4+1 -> 2026 | D5: =(D4*(1+$B$1))+C5 -> 10610000 | E5: =E4 -> 1 | F5: =D5*E5 -> 10610000 | H5: 0 | K5: 0 | N5: Growth Equity | O5: 0
A6: =A5+1 -> 2027 | D6: =(D5*(1+$B$1))+C6 -> 11257210 | E6: =E5 -> 1 | F6: =D6*E6 -> 11257210 | H6: 0 | K6: 0 | N6: Venture Capital | O6: 0
A7: =A6+1 -> 2028 | D7: =(D6*(1+$B$1))+C7 -> 11943900 | E7: =E6 -> 1 | F7: =D7*E7 -> 11943900 | H7: 0 | K7: 0 | N7: Fund of Funds | O7: 0
A8: =A7+1 -> 2029 | D8: =(D7*(1+$B$1))+C8 -> 12672478 | E8: =E7 -> 1 | F8: =D8*E8 -> 12672478 | H8: 0 | K8: 0 | N8: Secondary Funds | O8: 0
A9: =A8+1 -> 2030 | D9: =(D8*(1+$B$1))+C9 -> 13445499 | E9: =E8 -> 1 | F9: =D9*E9 -> 13445499 | H9: 0 | K9: 0 | N9: Private Credit | O9: 0
A10: =A9+1 -> 2031 | D10: =(D9*(1+$B$1))+C10 -> 14265674 | E10: =E9 -> 1 | F10: =D10*E10 -> 14265674 | H10: 0 | K10: 0 | N10: Real Estate | O10: 0
A11: =A10+1 -> 2032 | D11: =(D10*(1+$B$1))+C11 -> 15135880 | E11: =E10 -> 1 | F11: =D11*E11 -> 15135880 | H11: 0 | K11: 0
A12: =A11+1 -> 2033 | D12: =(D11*(1+$B$1))+C12 -> 16059169 | E12: =E11 -> 1 | F12: =D12*E12 -> 16059169 | H12: 0 | K12: 0 | N12: Total | O12: =SUM(O4:O10) -> 1
A13: =A12+1 -> 2034 | D13: =(D12*(1+$B$1))+C13 -> 17038778 | E13: =E12 -> 1 | F13: =D13*E13 -> 17038778 | H13: 0 | K13: 0
A14: =A13+1 -> 2035 | D14: =(D13*(1+$B$1))+C14 -> 18078144 | E14: =E13 -> 1 | F14: =D14*E14 -> 18078144 | H14: 0 | K14: 0
A15: =A14+1 -> 2036 | D15: =(D14*(1+$B$1))+C15 -> 19180911 | E15: =E14 -> 1 | F15: =D15*E15 -> 19180911 | H15: 0 | K15: 0
A16: =A15+1 -> 2037 | D16: =(D15*(1+$B$1))+C16 -> 20350946 | E16: =E15 -> 1 | F16: =D16*E16 -> 20350946 | H16: 0 | K16: 0
A17: =A16+1 -> 2038 | D17: =(D16*(1+$B$1))+C17 -> 21592354 | E17: =E16 -> 1 | F17: =D17*E17 -> 21592354 | H17: 0 | K17: 0
A18: =A17+1 -> 2039 | D18: =(D17*(1+$B$1))+C18 -> 22909488 | E18: =E17 -> 1 | F18: =D18*E18 -> 22909488 | H18: 0 | K18: 0
A27: EXISTING PORTFOLIO | B27: TO FILL IN WITH CONNECT OUTPUT | D27: Net Asset Value
A28: New Commitments | B28: Commitment | C28: % of Total Portfolio Value | D28: 2025 | E28: =D28+1 -> 2026 | F28: =E28+1 -> 2027 | G28: =F28+1 -> 2028 | H28: =G28+1 -> 2029 | I28: =H28+1 -> 2030 | J28: =I28+1 -> 2031 | K28: =J28+1 -> 2032 | L28: =K28+1 -> 2033 | ... R28: =Q28+1 -> 2039
B30: 0 | D30: 0 | E30: 0 | F30: 0 | G30: 0 | H30: 0 | I30: 0 | J30: 0 | K30: 0 | L30: 0 | M30: 0 | N30: 0 | O30: 0 | P30: 0 | Q30: 0 | R30: 0
D33: Annual Capital Called
A34: New Commitments | B34: Commitment | D34: =D$100 -> 2025 | E34: =E$100 -> 2026 | F34: =F$100 -> 2027 | G34: =G$100 -> 2028 | H34: =H$100 -> 2029 | I34: =I$100 -> 2030 | J34: =J$100 -> 2031 | K34: =K$100 -> 2032 | ... R34: =R$100 -> 2039
B36: 0 | D36: 0 | E36: 0 | F36: 0 | G36: 0 | H36: 0 | I36: 0 | J36: 0 | K36: 0 | L36: 0 | M36: 0 | N36: 0 | O36: 0 | P36: 0 | Q36: 0 | R36: 0
D38: Annual Distributions
A39: New Commitments | B39: Commitment | D39: =D$100 -> 2025 | E39: =E$100 -> 2026 | F39: =F$100 -> 2027 | G39: =G$100 -> 2028 | H39: =H$100 -> 2029 | I39: =I$100 -> 2030 | J39: =J$100 -> 2031 | K39: =K$100 -> 2032 | ... R39: =R$100 -> 2039
B41: 0 | D41: 0 | E41: 0 | F41: 0 | G41: 0 | H41: 0 | I41: 0 | J41: 0 | K41: 0 | L41: 0 | M41: 0 | N41: 0 | O41: 0 | P41: 0 | Q41: 0 | R41: 0
D43: Net Cash Flow
A44: New Commitments | B44: Commitment | D44: =D$100 -> 2025 | E44: =E$100 -> 2026 | F44: =F$100 -> 2027 | G44: =G$100 -> 2028 | H44: =H$100 -> 2029 | I44: =I$100 -> 2030 | J44: =J$100 -> 2031 | K44: =K$100 -> 2032 | ... R44: =R$100 -> 2039
B46: 0 | D46: =D36+D41 -> 0 | E46: =E36+E41 -> 0 | F46: =F36+F41 -> 0 | G46: =G36+G41 -> 0 | H46: =H36+H41 -> 0 | I46: =I36+I41 -> 0 | J46: =J36+J41 -> 0 | K46: =K36+K41 -> 0 | ... R46: =R36+R41 -> 0
A49: Net Cash Flow Cumulative | D49: =D46 -> 0 | E49: =D49+E46 -> 0 | F49: =E49+F46 -> 0 | G49: =F49+G46 -> 0 | H49: =G49+H46 -> 0 | I49: =H49+I46 -> 0 | J49: =I49+J46 -> 0 | K49: =J49+K46 -> 0 | L49: =K49+L46 -> 0 | ... R49: =Q49+R46 -> 0
A51: Cash invested | D51: Net Asset Value
A52: New Commitments | B52: Commitment | C52: % of Total Portfolio Value | D52: 2025 | E52: =D52+1 -> 2026 | F52: =E52+1 -> 2027 | G52: =F52+1 -> 2028 | H52: =G52+1 -> 2029 | I52: =H52+1 -> 2030 | J52: =I52+1 -> 2031 | K52: =J52+1 -> 2032 | L52: =K52+1 -> 2033 | ... R52: =Q52+1 -> 2039
B54: =SUM(K4:K18) -> 0 | C54: 10000000 | D54: =(C54+D146+D170)*(1+LTCMAs!$K$10) -> 4990428.6 | E54: =(D54+E146+E170)*(1+LTCMAs!$K$10) -> 4567421.1 | F54: =(E54+F146+F170)*(1+LTCMAs!$K$10) -> 3715115 | G54: =(F54+G146+G170)*(1+LTCMAs!$K$10) -> 2594610.2 | H54: =(G54+H146+H170)*(1+LTCMAs!$K$10) -> 1503831.8 | I54: =(H54+I146+I170)*(1+LTCMAs!$K$10) -> 596939.16 | J54: =(I54+J146+J170)*(1+LTCMAs!$K$10) -> 90520.41 | K54: =(J54+K146+K170)*(1+LTCMAs!$K$10) -> 21533.67 | ... R54: =(Q54+R146+R170)*(1+LTCMAs!$K$10) -> 8158798.7
D57: Annual Capital Called
A58: New Commitments | B58: Commitment | D58: =D$100 -> 2025 | E58: =E$100 -> 2026 | F58: =F$100 -> 2027 | G58: =G$100 -> 2028 | H58: =H$100 -> 2029 | I58: =I$100 -> 2030 | J58: =J$100 -> 2031 | K58: =K$100 -> 2032 | ... R58: =R$100 -> 2039
B60: =SUM(K4:K18) -> 0 | D60: =-K4 -> 0 | E60: =-$K5 -> 0 | F60: =-$K6 -> 0 | G60: =-$K7 -> 0 | H60: =-$K8 -> 0 | I60: =-$K9 -> 0 | J60: =-$K10 -> 0 | K60: =-$K11 -> 0 | L60: =-$K12 -> 0 | M60: =-$K13 -> 0 | N60: =-$K14 -> 0 | O60: =-$K15 -> 0 | P60: =-$K16 -> 0 | Q60: =-$K17 -> 0 | R60: =-$K18 -> 0
D62: Annual Distributions
A63: New Commitments | B63: Commitment | D63: =D$100 -> 2025 | E63: =E$100 -> 2026 | F63: =F$100 -> 2027 | G63: =G$100 -> 2028 | H63: =H$100 -> 2029 | I63: =I$100 -> 2030 | J63: =J$100 -> 2031 | K63: =K$100 -> 2032 | ... R63: =R$100 -> 2039
B65: =SUM(K4:K18) -> 0 | D65: =K4*$L$4 -> 0 | E65: =SUM($K4:$K5)*$L$4 -> 0 | F65: =SUM($K4:$K6)*$L$4 -> 0 | G65: =SUM($K4:$K7)*$L$4 -> 0 | H65: =SUM($K4:$K8)*$L$4 -> 0 | I65: =SUM($K4:$K9)*$L$4 -> 0 | J65: =SUM($K4:$K10)*$L$4 -> 0 | K65: =SUM($K4:$K11)*$L$4 -> 0 | L65: =SUM($K4:$K12)*$L$4 -> 0 | M65: =SUM($K4:$K13)*$L$4 -> 0 | N65: =SUM($K4:$K14)*$L$4 -> 0 | O65: =SUM($K4:$K15)*$L$4 -> 0 | P65: =SUM($K4:$K16)*$L$4 -> 0 | Q65: =SUM($K4:$K17)*$L$4 -> 0 | R65: =SUM($K4:$K18)*$L$4 -> 0
D67: Net Cash Flow
...

Sheet LTCMAs
K5: Compound Return
J6: US Cash | K6: 0.031
J7: US Agg Bonds | K7: 0.048
J8: AC World Equity | K8: 0.07
J9: Private Equity | K9: 0.102
J10: AC World Equity | K10: 0.07
J11: Evergreen | K11: =(K9*0.85)+(K7*0.15) -> 0.0939
J12: AC World Equity
R21: Not sure how they are getting to 6.4%

Sheet Aggregated Median CA data
E1: 12 | F1: 14 | G1: 16 | H1: 18 | J1: 3 | K1: 5 | L1: 7 | M1: 9 | O1: 13 | P1: 15 | Q1: 17 | R1: 19 | T1: 4 | U1: 6 | V1: 8 | W1: 10
E2: Cumulative | J2: Annual | O2: Cumulative Standard Deviation | T2: Annual Standard Deviation
C3: Year | D3: Year | E3: PICC | F3: DCC | G3: Net | H3: RVCC | J3: PICC | K3: DCC | L3: Net | M3: RVCC | O3: PICC | P3: DCC | Q3: Net | R3: RVCC | T3: PICC | U3: DCC | V3: Net | W3: RVCC
A4: Buyout | B4: 1 | C4: Year 1 | D4: 2025 | E4: =VLOOKUP($B4,'Global Buyout'!$A$4:$S$19,E$1,0) -> -0.17233232 | F4: =VLOOKUP($B4,'Global Buyout'!$A$4:$S$19,F$1,0) -> 0 | G4: =VLOOKUP($B4,'Global Buyout'!$A$4:$S$19,G$1,0) -> -0.17233232 | H4: =VLOOKUP($B4,'Global Buyout'!$A$4:$S$19,H$1,0) -> 0.15892278 | J4: =VLOOKUP($B4,'Global Buyout'!$A$4:$S$19,J$1,0) -> -0.17233232 | K4: =VLOOKUP($B4,'Global Buyout'!$A$4:$S$19,K$1,0) -> 0 | L4: =VLOOKUP($B4,'Global Buyout'!$A$4:$S$19,L$1,0) -> -0.17233232 | M4: =VLOOKUP($B4,'Global Buyout'!$A$4:$S$19,M$1,0) -> 0.15892278 | O4: =VLOOKUP($B4,'Global Buyout'!$A$4:$S$19,O$1,0) -> 0.071281608 | P4: =VLOOKUP($B4,'Global Buyout'!$A$4:$S$19,P$1,0) -> 0 | Q4: =VLOOKUP($B4,'Global Buyout'!$A$4:$S$19,Q$1,0) -> 0.071281608 | R4: =VLOOKUP($B4,'Global Buyout'!$A$4:$S$19,R$1,0) -> 0.06951452 | T4: =VLOOKUP($B4,'Global Buyout'!$A$4:$S$19,T$1,0) -> 0.066877745 | U4: =VLOOKUP($B4,'Global Buyout'!$A$4:$S$19,U$1,0) -> 0 | V4: =VLOOKUP($B4,'Global Buyout'!$A$4:$S$19,V$1,0) -> 0.066877745 | W4: =VLOOKUP($B4,'Global Buyout'!$A$4:$S$19,W$1,0) -> 0.06951452
A5: Buyout | B5: =B4+1 -> 2 | C5: Year 2 | D5: =D4+1 -> 2026 | E5: =VLOOKUP($B5,'Global Buyout'!$A$4:$S$19,E$1,0) -> -0.37092875 | F5: =VLOOKUP($B5,'Global Buyout'!$A$4:$S$19,F$1,0) -> 0.00076937362 | G5: =VLOOKUP($B5,'Global Buyout'!$A$4:$S$19,G$1,0) -> -0.37015937 | H5: =VLOOKUP($B5,'Global Buyout'!$A$4:$S$19,H$1,0) -> 0.35326424 | J5: =VLOOKUP($B5,'Global Buyout'!$A$4:$S$19,J$1,0) -> -0.19859642 | K5: =VLOOKUP($B5,'Global Buyout'!$A$4:$S$19,K$1,0) -> 0.00076937362 | L5: =VLOOKUP($B5,'Global Buyout'!$A$4:$S$19,L$1,0) -> -0.19782705 | M5: =VLOOKUP($B5,'Global Buyout'!$A$4:$S$19,M$1,0) -> 0.35326424 | O5: =VLOOKUP($B5,'Global Buyout'!$A$4:$S$19,O$1,0) -> 0.088515872 | P5: =VLOOKUP($B5,'Global Buyout'!$A$4:$S$19,P$1,0) -> 0.0021904756 | Q5: =VLOOKUP($B5,'Global Buyout'!$A$4:$S$19,Q$1,0) -> 0.088542971 | R5: =VLOOKUP($B5,'Global Buyout'!$A$4:$S$19,R$1,0) -> 0.087742984 | T5: =VLOOKUP($B5,'Global Buyout'!$A$4:$S$19,T$1,0) -> 0.052478489 | U5: =VLOOKUP($B5,'Global Buyout'!$A$4:$S$19,U$1,0) -> 0.0021904756 | V5: =VLOOKUP($B5,'Global Buyout'!$A$4:$S$19,V$1,0) -> 0.052524185 | W5: =VLOOKUP($B5,'Global Buyout'!$A$4:$S$19,W$1,0) -> 0.087742984
A6: Buyout | B6: =B5+1 -> 3 | C6: Year 3 | D6: =D5+1 -> 2027 | E6: =VLOOKUP($B6,'Global Buyout'!$A$4:$S$19,E$1,0) -> -0.58357967 | F6: =VLOOKUP($B6,'Global Buyout'!$A$4:$S$19,F$1,0) -> 0.021861211 | G6: =VLOOKUP($B6,'Global Buyout'!$A$4:$S$19,G$1,0) -> -0.56171846 | H6: =VLOOKUP($B6,'Global Buyout'!$A$4:$S$19,H$1,0) -> 0.57458796 | J6: =VLOOKUP($B6,'Global Buyout'!$A$4:$S$19,J$1,0) -> -0.21265092 | K6: =VLOOKUP($B6,'Global Buyout'!$A$4:$S$19,K$1,0) -> 0.021091838 | L6: =VLOOKUP($B6,'Global Buyout'!$A$4:$S$19,L$1,0) -> -0.19155909 | M6: =VLOOKUP($B6,'Global Buyout'!$A$4:$S$19,M$1,0) -> 0.57458796 | O6: =VLOOKUP($B6,'Global Buyout'!$A$4:$S$19,O$1,0) -> 0.10776371 | P6: =VLOOKUP($B6,'Global Buyout'!$A$4:$S$19,P$1,0) -> 0.019305403 | Q6: =VLOOKUP($B6,'Global Buyout'!$A$4:$S$19,Q$1,0) -> 0.10947929 | R6: =VLOOKUP($B6,'Global Buyout'!$A$4:$S$19,R$1,0) -> 0.11673267 | T6: =VLOOKUP($B6,'Global Buyout'!$A$4:$S$19,T$1,0) -> 0.061465086 | U6: =VLOOKUP($B6,'Global Buyout'!$A$4:$S$19,U$1,0) -> 0.01918073 | V6: =VLOOKUP($B6,'Global Buyout'!$A$4:$S$19,V$1,0) -> 0.064388331 | W6: =VLOOKUP($B6,'Global Buyout'!$A$4:$S$19,W$1,0) -> 0.11673267
A7: Buyout | B7: =B6+1 -> 4 | C7: Year 4 | D7: =D6+1 -> 2028 | E7: =VLOOKUP($B7,'Global Buyout'!$A$4:$S$19,E$1,0) -> -0.76905385 | F7: =VLOOKUP($B7,'Global Buyout'!$A$4:$S$19,F$1,0) -> 0.10738943 | G7: =VLOOKUP($B7,'Global Buyout'!$A$4:$S$19,G$1,0) -> -0.66166442 | H7: =VLOOKUP($B7,'Global Buyout'!$A$4:$S$19,H$1,0) -> 0.75100413 | J7: =VLOOKUP($B7,'Global Buyout'!$A$4:$S$19,J$1,0) -> -0.18547418 | K7: =VLOOKUP($B7,'Global Buyout'!$A$4:$S$19,K$1,0) -> 0.085528218 | L7: =VLOOKUP($B7,'Global Buyout'!$A$4:$S$19,L$1,0) -> -0.09994596 | M7: =VLOOKUP($B7,'Global Buyout'!$A$4:$S$19,M$1,0) -> 0.75100413 | O7: =VLOOKUP($B7,'Global Buyout'!$A$4:$S$19,O$1,0) -> 0.11925917 | P7: =VLOOKUP($B7,'Global Buyout'!$A$4:$S$19,P$1,0) -> 0.053021567 | Q7: =VLOOKUP($B7,'Global Buyout'!$A$4:$S$19,Q$1,0) -> 0.1305145 | R7: =VLOOKUP($B7,'Global Buyout'!$A$4:$S$19,R$1,0) -> 0.14393299 | T7: =VLOOKUP($B7,'Global Buyout'!$A$4:$S$19,T$1,0) -> 0.051085547 | U7: =VLOOKUP($B7,'Global Buyout'!$A$4:$S$19,U$1,0) -> 0.049382061 | V7: =VLOOKUP($B7,'Global Buyout'!$A$4:$S$19,V$1,0) -> 0.071051538 | W7: =VLOOKUP($B7,'Global Buyout'!$A$4:$S$19,W$1,0) -> 0.14393299
A8: Buyout | B8: =B7+1 -> 5 | C8: Year 5 | D8: =D7+1 -> 2029 | E8: =VLOOKUP($B8,'Global Buyout'!$A$4:$S$19,E$1,0) -> -0.88469937 | F8: =VLOOKUP($B8,'Global Buyout'!$A$4:$S$19,F$1,0) -> 0.27487377 | G8: =VLOOKUP($B8,'Global Buyout'!$A$4:$S$19,G$1,0) -> -0.6098256 | H8: =VLOOKUP($B8,'Global Buyout'!$A$4:$S$19,H$1,0) -> 0.84207639 | J8: =VLOOKUP($B8,'Global Buyout'!$A$4:$S$19,J$1,0) -> -0.11564552 | K8: =VLOOKUP($B8,'Global Buyout'!$A$4:$S$19,K$1,0) -> 0.16748434 | L8: =VLOOKUP($B8,'Global Buyout'!$A$4:$S$19,L$1,0) -> 0.051838821 | M8: =VLOOKUP($B8,'Global Buyout'!$A$4:$S$19,M$1,0) -> 0.84207639 | O8: =VLOOKUP($B8,'Global Buyout'!$A$4:$S$19,O$1,0) -> 0.13066982 | P8: =VLOOKUP($B8,'Global Buyout'!$A$4:$S$19,P$1,0) -> 0.10392418 | Q8: =VLOOKUP($B8,'Global Buyout'!$A$4:$S$19,Q$1,0) -> 0.16695759 | R8: =VLOOKUP($B8,'Global Buyout'!$A$4:$S$19,R$1,0) -> 0.18199231 | T8: =VLOOKUP($B8,'Global Buyout'!$A$4:$S$19,T$1,0) -> 0.05340274 | U8: =VLOOKUP($B8,'Global Buyout'!$A$4:$S$19,U$1,0) -> 0.089380914 | V8: =VLOOKUP($B8,'Global Buyout'!$A$4:$S$19,V$1,0) -> 0.10411916 | W8: =VLOOKUP($B8,'Global Buyout'!$A$4:$S$19,W$1,0) -> 0.18199231
A9: Buyout | B9: =B8+1 -> 6 | C9: Year 6 | D9: =D8+1 -> 2030 | E9: =VLOOKUP($B9,'Global Buyout'!$A$4:$S$19,E$1,0) -> -0.94336315 | F9: =VLOOKUP($B9,'Global Buyout'!$A$4:$S$19,F$1,0) -> 0.45826327 | G9: =VLOOKUP($B9,'Global Buyout'!$A$4:$S$19,G$1,0) -> -0.48509988 | H9: =VLOOKUP($B9,'Global Buyout'!$A$4:$S$19,H$1,0) -> 0.80576574 | J9: =VLOOKUP($B9,'Global Buyout'!$A$4:$S$19,J$1,0) -> -0.058663778 | K9: =VLOOKUP($B9,'Global Buyout'!$A$4:$S$19,K$1,0) -> 0.1833895 | L9: =VLOOKUP($B9,'Global Buyout'!$A$4:$S$19,L$1,0) -> 0.12472572 | M9: =VLOOKUP($B9,'Global Buyout'!$A$4:$S$19,M$1,0) -> 0.80576574 | O9: =VLOOKUP($B9,'Global Buyout'!$A$4:$S$19,O$1,0) -> 0.1353251 | P9: =VLOOKUP($B9,'Global Buyout'!$A$4:$S$19,P$1,0) -> 0.1381456 | Q9: =VLOOKUP($B9,'Global Buyout'!$A$4:$S$19,Q$1,0) -> 0.19338327 | R9: =VLOOKUP($B9,'Global Buyout'!$A$4:$S$19,R$1,0) -> 0.20880906 | T9: =VLOOKUP($B9,'Global Buyout'!$A$4:$S$19,T$1,0) -> 0.035189222 | U9: =VLOOKUP($B9,'Global Buyout'!$A$4:$S$19,U$1,0) -> 0.091016331 | V9: =VLOOKUP($B9,'Global Buyout'!$A$4:$S$19,V$1,0) -> 0.097582037 | W9: =VLOOKUP($B9,'Global Buyout'!$A$4:$S$19,W$1,0) -> 0.20880906
A10: Buyout | B10: =B9+1 -> 7 | C10: Year 7 | D10: =D9+1 -> 2031 | E10: =VLOOKUP($B10,'Global Buyout'!$A$4:$S$19,E$1,0) -> -0.96986043 | F10: =VLOOKUP($B10,'Global Buyout'!$A$4:$S$19,F$1,0) -> 0.70712164 | G10: =VLOOKUP($B10,'Global Buyout'!$A$4:$S$19,G$1,0) -> -0.26273879 | H10: =VLOOKUP($B10,'Global Buyout'!$A$4:$S$19,H$1,0) -> 0.73381849 | J10: =VLOOKUP($B10,'Global Buyout'!$A$4:$S$19,J$1,0) -> -0.026497281 | K10: =VLOOKUP($B10,'Global Buyout'!$A$4:$S$19,K$1,0) -> 0.24885836 | L10: =VLOOKUP($B10,'Global Buyout'!$A$4:$S$19,L$1,0) -> 0.22236108 | M10: =VLOOKUP($B10,'Global Buyout'!$A$4:$S$19,M$1,0) -> 0.73381849 | O10: =VLOOKUP($B10,'Global Buyout'!$A$4:$S$19,O$1,0) -> 0.13669497 | P10: =VLOOKUP($B10,'Global Buyout'!$A$4:$S$19,P$1,0) -> 0.1971422 | Q10: =VLOOKUP($B10,'Global Buyout'!$A$4:$S$19,Q$1,0) -> 0.23989698 | R10: =VLOOKUP($B10,'Global Buyout'!$A$4:$S$19,R$1,0) -> 0.23325753 | T10: =VLOOKUP($B10,'Global Buyout'!$A$4:$S$19,T$1,0) -> 0.019303637 | U10: =VLOOKUP($B10,'Global Buyout'!$A$4:$S$19,U$1,0) -> 0.14064438 | V10: =VLOOKUP($B10,'Global Buyout'!$A$4:$S$19,V$1,0) -> 0.14196293 | W10: =VLOOKUP($B10,'Global Buyout'!$A$4:$S$19,W$1,0) -> 0.23325753
A11: Buyout | B11: =B10+1 -> 8 | C11: Year 8 | D11: =D10+1 -> 2032 | E11: =VLOOKUP($B11,'Global Buyout'!$A$4:$S$19,E$1,0) -> -0.98544815 | F11: =VLOOKUP($B11,'Global Buyout'!$A$4:$S$19,F$1,0) -> 0.9493479 | G11: =VLOOKUP($B11,'Global Buyout'!$A$4:$S$19,G$1,0) -> -0.036100249 | H11: =VLOOKUP($B11,'Global Buyout'!$A$4:$S$19,H$1,0) -> 0.62205367 | J11: =VLOOKUP($B11,'Global Buyout'!$A$4:$S$19,J$1,0) -> -0.015587719 | K11: =VLOOKUP($B11,'Global Buyout'!$A$4:$S$19,K$1,0) -> 0.24222626 | L11: =VLOOKUP($B11,'Global Buyout'!$A$4:$S$19,L$1,0) -> 0.22663854 | M11: =VLOOKUP($B11,'Global Buyout'!$A$4:$S$19,M$1,0) -> 0.62205367 | O11: =VLOOKUP($B11,'Global Buyout'!$A$4:$S$19,O$1,0) -> 0.13737405 | P11: =VLOOKUP($B11,'Global Buyout'!$A$4:$S$19,P$1,0) -> 0.23161404 | Q11: =VLOOKUP($B11,'Global Buyout'!$A$4:$S$19,Q$1,0) -> 0.26928924 | R11: =VLOOKUP($B11,'Global Buyout'!$A$4:$S$19,R$1,0) -> 0.25240624 | T11: =VLOOKUP($B11,'Global Buyout'!$A$4:$S$19,T$1,0) -> 0.013642414 | U11: =VLOOKUP($B11,'Global Buyout'!$A$4:$S$19,U$1,0) -> 0.12157309 | V11: =VLOOKUP($B11,'Global Buyout'!$A$4:$S$19,V$1,0) -> 0.12233614 | W11: =VLOOKUP($B11,'Global Buyout'!$A$4:$S$19,W$1,0) -> 0.25240624
A12: Buyout | B12: =B11+1 -> 9 | C12: Year 9 | D12: =D11+1 -> 2033 | E12: =VLOOKUP($B12,'Global Buyout'!$A$4:$S$19,E$1,0) -> -0.99133125 | F12: =VLOOKUP($B12,'Global Buyout'!$A$4:$S$19,F$1,0) -> 1.147734 | G12: =VLOOKUP($B12,'Global Buyout'!$A$4:$S$19,G$1,0) -> 0.15640279 | H12: =VLOOKUP($B12,'Global Buyout'!$A$4:$S$19,H$1,0) -> 0.49289149 | J12: =VLOOKUP($B12,'Global Buyout'!$A$4:$S$19,J$1,0) -> -0.0058831056 | K12: =VLOOKUP($B12,'Global Buyout'!$A$4:$S$19,K$1,0) -> 0.19838614 | L12: =VLOOKUP($B12,'Global Buyout'!$A$4:$S$19,L$1,0) -> 0.19250304 | M12: =VLOOKUP($B12,'Global Buyout'!$A$4:$S$19,M$1,0) -> 0.49289149 | O12: =VLOOKUP($B12,'Global Buyout'!$A$4:$S$19,O$1,0) -> 0.13749786 | P12: =VLOOKUP($B12,'Global Buyout'!$A$4:$S$19,P$1,0) -> 0.25003305 | Q12: =VLOOKUP($B12,'Global Buyout'!$A$4:$S$19,Q$1,0) -> 0.28534574 | R12: =VLOOKUP($B12,'Global Buyout'!$A$4:$S$19,R$1,0) -> 0.26996866 | T12: =VLOOKUP($B12,'Global Buyout'!$A$4:$S$19,T$1,0) -> 0.0058337022 | U12: =VLOOKUP($B12,'Global Buyout'!$A$4:$S$19,U$1,0) -> 0.094188445 | V12: =VLOOKUP($B12,'Global Buyout'!$A$4:$S$19,V$1,0) -> 0.094368932 | W12: =VLOOKUP($B12,'Global Buyout'!$A$4:$S$19,W$1,0) -> 0.26996866
A13: Buyout | B13: =B12+1 -> 10 | C13: Year 10 | D13: =D12+1 -> 2034 | E13: =VLOOKUP($B13,'Global Buyout'!$A$4:$S$19,E$1,0) -> -0.99542107 | F13: =VLOOKUP($B13,'Global Buyout'!$A$4:$S$19,F$1,0) -> 1.2947567 | G13: =VLOOKUP($B13,'Global Buyout'!$A$4:$S$19,G$1,0) -> 0.29933565 | H13: =VLOOKUP($B13,'Global Buyout'!$A$4:$S$19,H$1,0) -> 0.40109496 | J13: =VLOOKUP($B13,'Global Buyout'!$A$4:$S$19,J$1,0) -> -0.0040898154 | K13: =VLOOKUP($B13,'Global Buyout'!$A$4:$S$19,K$1,0) -> 0.14702267 | L13: =VLOOKUP($B13,'Global Buyout'!$A$4:$S$19,L$1,0) -> 0.14293286 | M13: =VLOOKUP($B13,'Global Buyout'!$A$4:$S$19,M$1,0) -> 0.40109496 | O13: =VLOOKUP($B13,'Global Buyout'!$A$4:$S$19,O$1,0) -> 0.1375857 | P13: =VLOOKUP($B13,'Global Buyout'!$A$4:$S$19,P$1,0) -> 0.26634634 | Q13: =VLOOKUP($B13,'Global Buyout'!$A$4:$S$19,Q$1,0) -> 0.29978358 | R13: =VLOOKUP($B13,'Global Buyout'!$A$4:$S$19,R$1,0) -> 0.2785575 | T13: =VLOOKUP($B13,'Global Buyout'!$A$4:$S$19,T$1,0) -> 0.0049156313 | U13: =VLOOKUP($B13,'Global Buyout'!$A$4:$S$19,U$1,0) -> 0.091781506 | V13: =VLOOKUP($B13,'Global Buyout'!$A$4:$S$19,V$1,0) -> 0.091913047 | W13: =VLOOKUP($B13,'Global Buyout'!$A$4:$S$19,W$1,0) -> 0.2785575
A14: Buyout | B14: =B13+1 -> 11 | C14: Year 11 | D14: =D13+1 -> 2035 | E14: =VLOOKUP($B14,'Global Buyout'!$A$4:$S$19,E$1,0) -> -0.99813878 | F14: =VLOOKUP($B14,'Global Buyout'!$A$4:$S$19,F$1,0) -> 1.44689 | G14: =VLOOKUP($B14,'Global Buyout'!$A$4:$S$19,G$1,0) -> 0.44875124 | H14: =VLOOKUP($B14,'Global Buyout'!$A$4:$S$19,H$1,0) -> 0.30114431 | J14: =VLOOKUP($B14,'Global Buyout'!$A$4:$S$19,J$1,0) -> -0.0027177133 | K14: =VLOOKUP($B14,'Global Buyout'!$A$4:$S$19,K$1,0) -> 0.15213331 | L14: =VLOOKUP($B14,'Global Buyout'!$A$4:$S$19,L$1,0) -> 0.14941559 | M14: =VLOOKUP($B14,'Global Buyout'!$A$4:$S$19,M$1,0) -> 0.30114431 | O14: =VLOOKUP($B14,'Global Buyout'!$A$4:$S$19,O$1,0) -> 0.13762888 | P14: =VLOOKUP($B14,'Global Buyout'!$A$4:$S$19,P$1,0) -> 0.28483522 | Q14: =VLOOKUP($B14,'Global Buyout'!$A$4:$S$19,Q$1,0) -> 0.31634287 | R14: =VLOOKUP($B14,'Global Buyout'!$A$4:$S$19,R$1,0) -> 0.28667331 | T14: =VLOOKUP($B14,'Global Buyout'!$A$4:$S$19,T$1,0) -> 0.0034473203 | U14: =VLOOKUP($B14,'Global Buyout'!$A$4:$S$19,U$1,0) -> 0.10094914 | V14: =VLOOKUP($B14,'Global Buyout'!$A$4:$S$19,V$1,0) -> 0.10100798 | W14: =VLOOKUP($B14,'Global Buyout'!$A$4:$S$19,W$1,0) -> 0.28667331
A15: Buyout | B15: =B14+1 -> 12 | C15: Year 12 | D15: =D14+1 -> 2036 | E15: =VLOOKUP($B15,'Global Buyout'!$A$4:$S$19,E$1,0) -> -0.99963473 | F15: =VLOOKUP($B15,'Global Buyout'!$A$4:$S$19,F$1,0) -> 1.529232 | G15: =VLOOKUP($B15,'Global Buyout'!$A$4:$S$19,G$1,0) -> 0.52959724 | H15: =VLOOKUP($B15,'Global Buyout'!$A$4:$S$19,H$1,0) -> 0.23129646 | J15: =VLOOKUP($B15,'Global Buyout'!$A$4:$S$19,J$1,0) -> -0.0014959473 | K15: =VLOOKUP($B15,'Global Buyout'!$A$4:$S$19,K$1,0) -> 0.08234195 | L15: =VLOOKUP($B15,'Global Buyout'!$A$4:$S$19,L$1,0) -> 0.080846002 | M15: =VLOOKUP($B15,'Global Buyout'!$A$4:$S$19,M$1,0) -> 0.23129646 | O15: =VLOOKUP($B15,'Global Buyout'!$A$4:$S$19,O$1,0) -> 0.13765502 | P15: =VLOOKUP($B15,'Global Buyout'!$A$4:$S$19,P$1,0) -> 0.28989953 | Q15: =VLOOKUP($B15,'Global Buyout'!$A$4:$S$19,Q$1,0) -> 0.32092155 | R15: =VLOOKUP($B15,'Global Buyout'!$A$4:$S$19,R$1,0) -> 0.28970275 | T15: =VLOOKUP($B15,'Global Buyout'!$A$4:$S$19,T$1,0) -> 0.0026823972 | U15: =VLOOKUP($B15,'Global Buyout'!$A$4:$S$19,U$1,0) -> 0.053950316 | V15: =VLOOKUP($B15,'Global Buyout'!$A$4:$S$19,V$1,0) -> 0.054016959 | W15: =VLOOKUP($B15,'Global Buyout'!$A$4:$S$19,W$1,0) -> 0.28970275
A16: Buyout | B16: =B15+1 -> 13 | C16: Year 13 | D16: =D15+1 -> 2037 | E16: =VLOOKUP($B16,'Global Buyout'!$A$4:$S$19,E$1,0) -> -1.0007196 | F16: =VLOOKUP($B16,'Global Buyout'!$A$4:$S$19,F$1,0) -> 1.5929652 | G16: =VLOOKUP($B16,'Global Buyout'!$A$4:$S$19,G$1,0) -> 0.59224565 | H16: =VLOOKUP($B16,'Global Buyout'!$A$4:$S$19,H$1,0) -> 0.17915683 | J16: =VLOOKUP($B16,'Global Buyout'!$A$4:$S$19,J$1,0) -> -0.0010848328 | K16: =VLOOKUP($B16,'Global Buyout'!$A$4:$S$19,K$1,0) -> 0.063733239 | L16: =VLOOKUP($B16,'Global Buyout'!$A$4:$S$19,L$1,0) -> 0.062648406 | M16: =VLOOKUP($B16,'Global Buyout'!$A$4:$S$19,M$1,0) -> 0.17915683 | O16: =VLOOKUP($B16,'Global Buyout'!$A$4:$S$19,O$1,0) -> 0.13767406 | P16: =VLOOKUP($B16,'Global Buyout'!$A$4:$S$19,P$1,0) -> 0.29485905 | Q16: =VLOOKUP($B16,'Global Buyout'!$A$4:$S$19,Q$1,0) -> 0.32541666 | R16: =VLOOKUP($B16,'Global Buyout'!$A$4:$S$19,R$1,0) -> 0.2919659 | T16: =VLOOKUP($B16,'Global Buyout'!$A$4:$S$19,T$1,0) -> 0.0022895222 | U16: =VLOOKUP($B16,'Global Buyout'!$A$4:$S$19,U$1,0) -> 0.053852746 | V16: =VLOOKUP($B16,'Global Buyout'!$A$4:$S$19,V$1,0) -> 0.053901393 | W16: =VLOOKUP($B16,'Global Buyout'!$A$4:$S$19,W$1,0) -> 0.2919659
A17: Buyout | B17: =B16+1 -> 14 | C17: Year 14 | D17: =D16+1 -> 2038 | E17: =VLOOKUP($B17,'Global Buyout'!$A$4:$S$19,E$1,0) -> -1.0008108 | F17: =VLOOKUP($B17,'Global Buyout'!$A$4:$S$19,F$1,0) -> 1.626022 | G17: =VLOOKUP($B17,'Global Buyout'!$A$4:$S$19,G$1,0) -> 0.62521126 | H17: =VLOOKUP($B17,'Global Buyout'!$A$4:$S$19,H$1,0) -> 0.15463364 | J17: =VLOOKUP($B17,'Global Buyout'!$A$4:$S$19,J$1,0) -> -9.1196912e-05 | K17: =VLOOKUP($B17,'Global Buyout'!$A$4:$S$19,K$1,0) -> 0.033056808 | L17: =VLOOKUP($B17,'Global Buyout'!$A$4:$S$19,L$1,0) -> 0.032965611 | M17: =VLOOKUP($B17,'Global Buyout'!$A$4:$S$19,M$1,0) -> 0.15463364 | O17: =VLOOKUP($B17,'Global Buyout'!$A$4:$S$19,O$1,0) -> 0.1376747 | P17: =VLOOKUP($B17,'Global Buyout'!$A$4:$S$19,P$1,0) -> 0.29738637 | Q17: =VLOOKUP($B17,'Global Buyout'!$A$4:$S$19,Q$1,0) -> 0.32770867 | R17: =VLOOKUP($B17,'Global Buyout'!$A$4:$S$19,R$1,0) -> 0.29242259 | T17: =VLOOKUP($B17,'Global Buyout'!$A$4:$S$19,T$1,0) -> 0.00042129722 | U17: =VLOOKUP($B17,'Global Buyout'!$A$4:$S$19,U$1,0) -> 0.038688433 | V17: =VLOOKUP($B17,'Global Buyout'!$A$4:$S$19,V$1,0) -> 0.038690727 | W17: =VLOOKUP($B17,'Global Buyout'!$A$4:$S$19,W$1,0) -> 0.29242259
A18: Buyout | B18: =B17+1 -> 15 | C18: Year 15 | D18: =D17+1 -> 2039 | E18: =VLOOKUP($B18,'Global Buyout'!$A$4:$S$19,E$1,0) -> -1.0012032 | F18: =VLOOKUP($B18,'Global Buyout'!$A$4:$S$19,F$1,0) -> 1.6563195 | G18: =VLOOKUP($B18,'Global Buyout'!$A$4:$S$19,G$1,0) -> 0.65511637 | H18: =VLOOKUP($B18,'Global Buyout'!$A$4:$S$19,H$1,0) -> 0.14093299 | J18: =VLOOKUP($B18,'Global Buyout'!$A$4:$S$19,J$1,0) -> -0.00039239188 | K18: =VLOOKUP($B18,'Global Buyout'!$A$4:$S$19,K$1,0) -> 0.030297501 | L18: =VLOOKUP($B18,'Global Buyout'!$A$4:$S$19,L$1,0) -> 0.029905109 | M18: =VLOOKUP($B18,'Global Buyout'!$A$4:$S$19,M$1,0) -> 0.14093299 | O18: =VLOOKUP($B18,'Global Buyout'!$A$4:$S$19,O$1,0) -> 0.13767792 | P18: =VLOOKUP($B18,'Global Buyout'!$A$4:$S$19,P$1,0) -> 0.29965017 | Q18: =VLOOKUP($B18,'Global Buyout'!$A$4:$S$19,Q$1,0) -> 0.32976573 | R18: =VLOOKUP($B18,'Global Buyout'!$A$4:$S$19,R$1,0) -> 0.29284389 | T18: =VLOOKUP($B18,'Global Buyout'!$A$4:$S$19,T$1,0) -> 0.00094170607 | U18: =VLOOKUP($B18,'Global Buyout'!$A$4:$S$19,U$1,0) -> 0.036763758 | V18: =VLOOKUP($B18,'Global Buyout'!$A$4:$S$19,V$1,0) -> 0.036775817 | W18: =VLOOKUP($B18,'Global Buyout'!$A$4:$S$19,W$1,0) -> 0.29284389 | Y18: =SUM(H18,F18)/-E18 -> 1.7950927 | Z18: =SUM(M18,K4:K18)/-SUM(J4:J18) -> 1.7950927 | AA18: =Y18=Z18 -> TRUE
A20: Growth Equity | B20: 1 | C20: Year 1 | D20: =D4 -> 2025 | E20: =VLOOKUP($B20,'Global Growth Equity'!$A$4:$S$19,E$1,0) -> -0.2353498 | F20: =VLOOKUP($B20,'Global Growth Equity'!$A$4:$S$19,F$1,0) -> 0 | G20: =VLOOKUP($B20,'Global Growth Equity'!$A$4:$S$19,G$1,0) -> -0.2353498 | H20: =VLOOKUP($B20,'Global Growth Equity'!$A$4:$S$19,H$1,0) -> 0.21842407 | J20: =VLOOKUP($B20,'Global Growth Equity'!$A$4:$S$19,J$1,0) -> -0.2353498 | K20: =VLOOKUP($B20,'Global Growth Equity'!$A$4:$S$19,K$1,0) -> 0 | L20: =VLOOKUP($B20,'Global Growth Equity'!$A$4:$S$19,L$1,0) -> -0.2353498 | M20: =VLOOKUP($B20,'Global Growth Equity'!$A$4:$S$19,M$1,0) -> 0.21842407 | O20: =VLOOKUP($B20,'Global Growth Equity'!$A$4:$S$19,O$1,0) -> 0.089701165 | P20: =VLOOKUP($B20,'Global Growth Equity'!$A$4:$S$19,P$1,0) -> 0 | Q20: =VLOOKUP($B20,'Global Growth Equity'!$A$4:$S$19,Q$1,0) -> 0.089701165 | R20: =VLOOKUP($B20,'Global Growth Equity'!$A$4:$S$19,R$1,0) -> 0.088806226 | T20: =VLOOKUP($B20,'Global Growth Equity'!$A$4:$S$19,T$1,0) -> 0.08549831 | U20: =VLOOKUP($B20,'Global Growth Equity'!$A$4:$S$19,U$1,0) -> 0 | V20: =VLOOKUP($B20,'Global Growth Equity'!$A$4:$S$19,V$1,0) -> 0.08549831 | W20: =VLOOKUP($B20,'Global Growth Equity'!$A$4:$S$19,W$1,0) -> 0.088806226
A21: Growth Equity | B21: =B20+1 -> 2 | C21: Year 2 | D21: =D5 -> 2026 | E21: =VLOOKUP($B21,'Global Growth Equity'!$A$4:$S$19,E$1,0) -> -0.47043254 | F21: =VLOOKUP($B21,'Global Growth Equity'!$A$4:$S$19,F$1,0) -> 0.00024311022 | G21: =VLOOKUP($B21,'Global Growth Equity'!$A$4:$S$19,G$1,0) -> -0.47018943 | H21: =VLOOKUP($B21,'Global Growth Equity'!$A$4:$S$19,H$1,0) -> 0.45579695 | J21: =VLOOKUP($B21,'Global Growth Equity'!$A$4:$S$19,J$1,0) -> -0.23508274 | K21: =VLOOKUP($B21,'Global Growth Equity'!$A$4:$S$19,K$1,0) -> 0.00024311022 | L21: =VLOOKUP($B21,'Global Growth Equity'!$A$4:$S$19,L$1,0) -> -0.23483963 | M21: =VLOOKUP($B21,'Global Growth Equity'!$A$4:$S$19,M$1,0) -> 0.45579695 | O21: =VLOOKUP($B21,'Global Growth Equity'!$A$4:$S$19,O$1,0) -> 0.11079509 | P21: =VLOOKUP($B21,'Global Growth Equity'!$A$4:$S$19,P$1,0) -> 0.001190992 | Q21: =VLOOKUP($B21,'Global Growth Equity'!$A$4:$S$19,Q$1,0) -> 0.1108015 | R21: =VLOOKUP($B21,'Global Growth Equity'!$A$4:$S$19,R$1,0) -> 0.11935407 | T21: =VLOOKUP($B21,'Global Growth Equity'!$A$4:$S$19,T$1,0) -> 0.065032715 | U21: =VLOOKUP($B21,'Global Growth Equity'!$A$4:$S$19,U$1,0) -> 0.001190992 | V21: =VLOOKUP($B21,'Global Growth Equity'!$A$4:$S$19,V$1,0) -> 0.06504362 | W21: =VLOOKUP($B21,'Global Growth Equity'!$A$4:$S$19,W$1,0) -> 0.11935407
A22: Growth Equity | B22: =B21+1 -> 3 | C22: Year 3 | D22: =D6 -> 2027 | E22: =VLOOKUP($B22,'Global Growth Equity'!$A$4:$S$19,E$1,0) -> -0.69057851 | F22: =VLOOKUP($B22,'Global Growth Equity'!$A$4:$S$19,F$1,0) -> 0.011903643 | G22: =VLOOKUP($B22,'Global Growth Equity'!$A$4:$S$19,G$1,0) -> -0.67867486 | H22: =VLOOKUP($B22,'Global Growth Equity'!$A$4:$S$19,H$1,0) -> 0.69115782 | J22: =VLOOKUP($B22,'Global Growth Equity'!$A$4:$S$19,J$1,0) -> -0.22014597 | K22: =VLOOKUP($B22,'Global Growth Equity'!$A$4:$S$19,K$1,0) -> 0.011660532 | L22: =VLOOKUP($B22,'Global Growth Equity'!$A$4:$S$19,L$1,0) -> -0.20848544 | M22: =VLOOKUP($B22,'Global Growth Equity'!$A$4:$S$19,M$1,0) -> 0.69115782 | O22: =VLOOKUP($B22,'Global Growth Equity'!$A$4:$S$19,O$1,0) -> 0.13942613 | P22: =VLOOKUP($B22,'Global Growth Equity'!$A$4:$S$19,P$1,0) -> 0.015479718 | Q22: =VLOOKUP($B22,'Global Growth Equity'!$A$4:$S$19,Q$1,0) -> 0.14028281 | R22: =VLOOKUP($B22,'Global Growth Equity'!$A$4:$S$19,R$1,0) -> 0.17394611 | T22: =VLOOKUP($B22,'Global Growth Equity'!$A$4:$S$19,T$1,0) -> 0.084640967 | U22: =VLOOKUP($B22,'Global Growth Equity'!$A$4:$S$19,U$1,0) -> 0.015433833 | V22: =VLOOKUP($B22,'Global Growth Equity'!$A$4:$S$19,V$1,0) -> 0.0860366 | W22: =VLOOKUP($B22,'Global Growth Equity'!$A$4:$S$19,W$1,0) -> 0.17394611
A23: Growth Equity | B23: =B22+1 -> 4 | C23: Year 4 | D23: =D7 -> 2028 | E23: =VLOOKUP($B23,'Global Growth Equity'!$A$4:$S$19,E$1,0) -> -0.85917011 | F23: =VLOOKUP($B23,'Global Growth Equity'!$A$4:$S$19,F$1,0) -> 0.063652187 | G23: =VLOOKUP($B23,'Global Growth Equity'!$A$4:$S$19,G$1,0) -> -0.79551793 | H23: =VLOOKUP($B23,'Global Growth Equity'!$A$4:$S$19,H$1,0) -> 0.8910481 | J23: =VLOOKUP($B23,'Global Growth Equity'!$A$4:$S$19,J$1,0) -> -0.16859161 | K23: =VLOOKUP($B23,'Global Growth Equity'!$A$4:$S$19,K$1,0) -> 0.051748545 | L23: =VLOOKUP($B23,'Global Growth Equity'!$A$4:$S$19,L$1,0) -> -0.11684306 | M23: =VLOOKUP($B23,'Global Growth Equity'!$A$4:$S$19,M$1,0) -> 0.8910481 | O23: =VLOOKUP($B23,'Global Growth Equity'!$A$4:$S$19,O$1,0) -> 0.15183577 | P23: =VLOOKUP($B23,'Global Growth Equity'!$A$4:$S$19,P$1,0) -> 0.039524195 | Q23: =VLOOKUP($B23,'Global Growth Equity'!$A$4:$S$19,Q$1,0) -> 0.15689571 | R23: =VLOOKUP($B23,'Global Growth Equity'!$A$4:$S$19,R$1,0) -> 0.21929015 | T23: =VLOOKUP($B23,'Global Growth Equity'!$A$4:$S$19,T$1,0) -> 0.060120332 | U23: =VLOOKUP($B23,'Global Growth Equity'!$A$4:$S$19,U$1,0) -> 0.036366748 | V23: =VLOOKUP($B23,'Global Growth Equity'!$A$4:$S$19,V$1,0) -> 0.070263751 | W23: =VLOOKUP($B23,'Global Growth Equity'!$A$4:$S$19,W$1,0) -> 0.21929015
A24: Growth Equity | B24: =B23+1 -> 5 | C24: Year 5 | D24: =D8 -> 2029 | E24: =VLOOKUP($B24,'Global Growth Equity'!$A$4:$S$19,E$1,0) -> -0.9546117 | F24: =VLOOKUP($B24,'Global Growth Equity'!$A$4:$S$19,F$1,0) -> 0.15858256 | G24: =VLOOKUP($B24,'Global Growth Equity'!$A$4:$S$19,G$1,0) -> -0.79602914 | H24: =VLOOKUP($B24,'Global Growth Equity'!$A$4:$S$19,H$1,0) -> 0.96836953 | J24: =VLOOKUP($B24,'Global Growth Equity'!$A$4:$S$19,J$1,0) -> -0.095441582 | K24: =VLOOKUP($B24,'Global Growth Equity'!$A$4:$S$19,K$1,0) -> 0.094930372 | L24: =VLOOKUP($B24,'Global Growth Equity'!$A$4:$S$19,L$1,0) -> -0.00051121048 | M24: =VLOOKUP($B24,'Global Growth Equity'!$A$4:$S$19,M$1,0) -> 0.96836953 | O24: =VLOOKUP($B24,'Global Growth Equity'!$A$4:$S$19,O$1,0) -> 0.15897928 | P24: =VLOOKUP($B24,'Global Growth Equity'!$A$4:$S$19,P$1,0) -> 0.069805568 | Q24: =VLOOKUP($B24,'Global Growth Equity'!$A$4:$S$19,Q$1,0) -> 0.17362958 | R24: =VLOOKUP($B24,'Global Growth Equity'!$A$4:$S$19,R$1,0) -> 0.25121057 | T24: =VLOOKUP($B24,'Global Growth Equity'!$A$4:$S$19,T$1,0) -> 0.047120184 | U24: =VLOOKUP($B24,'Global Growth Equity'!$A$4:$S$19,U$1,0) -> 0.057538294 | V24: =VLOOKUP($B24,'Global Growth Equity'!$A$4:$S$19,V$1,0) -> 0.074370471 | W24: =VLOOKUP($B24,'Global Growth Equity'!$A$4:$S$19,W$1,0) -> 0.25121057
A25: Growth Equity | B25: =B24+1 -> 6 | C25: Year 6 | D25: =D9 -> 2030 | E25: =VLOOKUP($B25,'Global Growth Equity'!$A$4:$S$19,E$1,0) -> -1.013275 | F25: =VLOOKUP($B25,'Global Growth Equity'!$A$4:$S$19,F$1,0) -> 0.32159416 | G25: =VLOOKUP($B25,'Global Growth Equity'!$A$4:$S$19,G$1,0) -> -0.6916808 | H25: =VLOOKUP($B25,'Global Growth Equity'!$A$4:$S$19,H$1,0) -> 0.98365813 | J25: =VLOOKUP($B25,'Global Growth Equity'!$A$4:$S$19,J$1,0) -> -0.058663269 | K25: =VLOOKUP($B25,'Global Growth Equity'!$A$4:$S$19,K$1,0) -> 0.16301161 | L25: =VLOOKUP($B25,'Global Growth Equity'!$A$4:$S$19,L$1,0) -> 0.10434834 | M25: =VLOOKUP($B25,'Global Growth Equity'!$A$4:$S$19,M$1,0) -> 0.98365813 | O25: =VLOOKUP($B25,'Global Growth Equity'!$A$4:$S$19,O$1,0) -> 0.16248142 | P25: =VLOOKUP($B25,'Global Growth Equity'!$A$4:$S$19,P$1,0) -> 0.11106188 | Q25: =VLOOKUP($B25,'Global Growth Equity'!$A$4:$S$19,Q$1,0) -> 0.19681197 | R25: =VLOOKUP($B25,'Global Growth Equity'!$A$4:$S$19,R$1,0) -> 0.27144531 | T25: =VLOOKUP($B25,'Global Growth Equity'!$A$4:$S$19,T$1,0) -> 0.033552923 | U25: =VLOOKUP($B25,'Global Growth Equity'!$A$4:$S$19,U$1,0) -> 0.086382425 | V25: =VLOOKUP($B25,'Global Growth Equity'!$A$4:$S$19,V$1,0) -> 0.092669962 | W25: =VLOOKUP($B25,'Global Growth Equity'!$A$4:$S$19,W$1,0) -> 0.27144531
A26: Growth Equity | B26: =B25+1 -> 7 | C26: Year 7 | D26: =D10 -> 2031 | E26: =VLOOKUP($B26,'Global Growth Equity'!$A$4:$S$19,E$1,0) -> -1.0370047 | F26: =VLOOKUP($B26,'Global Growth Equity'!$A$4:$S$19,F$1,0) -> 0.46401681 | G26: =VLOOKUP($B26,'Global Growth Equity'!$A$4:$S$19,G$1,0) -> -0.57298789 | H26: =VLOOKUP($B26,'Global Growth Equity'!$A$4:$S$19,H$1,0) -> 0.9800405 | J26: =VLOOKUP($B26,'Global Growth Equity'!$A$4:$S$19,J$1,0) -> -0.023729732 | K26: =VLOOKUP($B26,'Global Growth Equity'!$A$4:$S$19,K$1,0) -> 0.14242264 | L26: =VLOOKUP($B26,'Global Growth Equity'!$A$4:$S$19,L$1,0) -> 0.11869291 | M26: =VLOOKUP($B26,'Global Growth Equity'!$A$4:$S$19,M$1,0) -> 0.9800405 | O26: =VLOOKUP($B26,'Global Growth Equity'!$A$4:$S$19,O$1,0) -> 0.16327326 | P26: =VLOOKUP($B26,'Global Growth Equity'!$A$4:$S$19,P$1,0) -> 0.14666163 | Q26: =VLOOKUP($B26,'Global Growth Equity'!$A$4:$S$19,Q$1,0) -> 0.21947162 | R26: =VLOOKUP($B26,'Global Growth Equity'!$A$4:$S$19,R$1,0) -> 0.29182664 | T26: =VLOOKUP($B26,'Global Growth Equity'!$A$4:$S$19,T$1,0) -> 0.016060683 | U26: =VLOOKUP($B26,'Global Growth Equity'!$A$4:$S$19,U$1,0) -> 0.095785662 | V26: =VLOOKUP($B26,'Global Growth Equity'!$A$4:$S$19,V$1,0) -> 0.097122801 | W26: =VLOOKUP($B26,'Global Growth Equity'!$A$4:$S$19,W$1,0) -> 0.29182664
A27: Growth Equity | B27: =B26+1 -> 8 | C27: Year 8 | D27: =D11 -> 2032 | E27: =VLOOKUP($B27,'Global Growth Equity'!$A$4:$S$19,E$1,0) -> -1.0514974 | F27: =VLOOKUP($B27,'Global Growth Equity'!$A$4:$S$19,F$1,0) -> 0.64288259 | G27: =VLOOKUP($B27,'Global Growth Equity'!$A$4:$S$19,G$1,0) -> -0.40861484 | H27: =VLOOKUP($B27,'Global Growth Equity'!$A$4:$S$19,H$1,0) -> 0.8619287 | J27: =VLOOKUP($B27,'Global Growth Equity'!$A$4:$S$19,J$1,0) -> -0.014492728 | K27: =VLOOKUP($B27,'Global Growth Equity'!$A$4:$S$19,K$1,0) -> 0.17886578 | L27: =VLOOKUP($B27,'Global Growth Equity'!$A$4:$S$19,L$1,0) -> 0.16437305 | M27: =VLOOKUP($B27,'Global Growth Equity'!$A$4:$S$19,M$1,0) -> 0.8619287 | O27: =VLOOKUP($B27,'Global Growth Equity'!$A$4:$S$19,O$1,0) -> 0.1636578 | P27: =VLOOKUP($B27,'Global Growth Equity'!$A$4:$S$19,P$1,0) -> 0.18196616 | Q27: =VLOOKUP($B27,'Global Growth Equity'!$A$4:$S$19,Q$1,0) -> 0.24473569 | R27: =VLOOKUP($B27,'Global Growth Equity'!$A$4:$S$19,R$1,0) -> 0.31195581 | T27: =VLOOKUP($B27,'Global Growth Equity'!$A$4:$S$19,T$1,0) -> 0.011212426 | U27: =VLOOKUP($B27,'Global Growth Equity'!$A$4:$S$19,U$1,0) -> 0.1077128 | V27: =VLOOKUP($B27,'Global Growth Equity'!$A$4:$S$19,V$1,0) -> 0.10829481 | W27: =VLOOKUP($B27,'Global Growth Equity'!$A$4:$S$19,W$1,0) -> 0.31195581
A28: Growth Equity | B28: =B27+1 -> 9 | C28: Year 9 | D28: =D12 -> 2033 | E28: =VLOOKUP($B28,'Global Growth Equity'!$A$4:$S$19,E$1,0) -> -1.0588448 | F28: =VLOOKUP($B28,'Global Growth Equity'!$A$4:$S$19,F$1,0) -> 0.82068178 | G28: =VLOOKUP($B28,'Global Growth Equity'!$A$4:$S$19,G$1,0) -> -0.23816306 | H28: =VLOOKUP($B28,'Global Growth Equity'!$A$4:$S$19,H$1,0) -> 0.74636821 | J28: =VLOOKUP($B28,'Global Growth Equity'!$A$4:$S$19,J$1,0) -> -0.0073474172 | K28: =VLOOKUP($B28,'Global Growth Equity'!$A$4:$S$19,K$1,0) -> 0.17779919 | L28: =VLOOKUP($B28,'Global Growth Equity'!$A$4:$S$19,L$1,0) -> 0.17045178 | M28: =VLOOKUP($B28,'Global Growth Equity'!$A$4:$S$19,M$1,0) -> 0.74636821 | O28: =VLOOKUP($B28,'Global Growth Equity'!$A$4:$S$19,O$1,0) -> 0.16382728 | P28: =VLOOKUP($B28,'Global Growth Equity'!$A$4:$S$19,P$1,0) -> 0.2184713 | Q28: =VLOOKUP($B28,'Global Growth Equity'!$A$4:$S$19,Q$1,0) -> 0.27307341 | R28: =VLOOKUP($B28,'Global Growth Equity'!$A$4:$S$19,R$1,0) -> 0.33221333 | T28: =VLOOKUP($B28,'Global Growth Equity'!$A$4:$S$19,T$1,0) -> 0.0074500777 | U28: =VLOOKUP($B28,'Global Growth Equity'!$A$4:$S$19,U$1,0) -> 0.12090504 | V28: =VLOOKUP($B28,'Global Growth Equity'!$A$4:$S$19,V$1,0) -> 0.12113436 | W28: =VLOOKUP($B28,'Global Growth Equity'!$A$4:$S$19,W$1,0) -> 0.33221333
